<?xml version="1.0" ?>
<robot name="diff_bot" xmlns:xacro="http://www.ros.org/wiki/xacro">

<xacro:include filename="$(find diff_bot_description)/urdf/materials.xacro" />
<xacro:include filename="$(find diff_bot_description)/urdf/diff_bot.trans" />
<xacro:include filename="$(find diff_bot_description)/urdf/diff_bot.gazebo" />
<link name="base_link">
  <inertial>
    <origin xyz="0.001236479549238988 1.7595715933608262e-17 0.05018173541387255" rpy="0 0 0"/>
    <mass value="16.23016292342114"/>
    <inertia ixx="0.056336" iyy="0.058867" izz="0.107316" ixy="0.0" iyz="0.0" ixz="-0.000699"/>
  </inertial>
  <visual>
    <origin xyz="0 0 0" rpy="0 0 0"/>
    <geometry>
      <mesh filename="package://diff_bot_description/meshes/base_link.stl" scale="0.001 0.001 0.001"/>
    </geometry>
    <material name="silver"/>
  </visual>
  <collision>
    <origin xyz="0 0 0" rpy="0 0 0"/>
    <geometry>
      <mesh filename="package://diff_bot_description/meshes/base_link.stl" scale="0.001 0.001 0.001"/>
    </geometry>
  </collision>
</link>

<link name="left_wheel_1">
  <inertial>
    <origin xyz="-5.790023100122029e-18 0.012499999999999997 0.0" rpy="0 0 0"/>
    <mass value="1.541343895667492"/>
    <inertia ixx="0.001044" iyy="0.001927" izz="0.001044" ixy="0.0" iyz="0.0" ixz="0.0"/>
  </inertial>
  <visual>
    <origin xyz="-0.0 -0.1 -0.05" rpy="0 0 0"/>
    <geometry>
      <mesh filename="package://diff_bot_description/meshes/left_wheel_1.stl" scale="0.001 0.001 0.001"/>
    </geometry>
    <material name="silver"/>
  </visual>
  <collision>
    <origin xyz="-0.0 -0.1 -0.05" rpy="0 0 0"/>
    <geometry>
      <mesh filename="package://diff_bot_description/meshes/left_wheel_1.stl" scale="0.001 0.001 0.001"/>
    </geometry>
  </collision>
</link>

<link name="right_wheel_1">
  <inertial>
    <origin xyz="-5.790023100122029e-18 -0.012499999999999997 0.0" rpy="0 0 0"/>
    <mass value="1.541343895667492"/>
    <inertia ixx="0.001044" iyy="0.001927" izz="0.001044" ixy="0.0" iyz="-0.0" ixz="-0.0"/>
  </inertial>
  <visual>
    <origin xyz="-0.0 0.1 -0.05" rpy="0 0 0"/>
    <geometry>
      <mesh filename="package://diff_bot_description/meshes/right_wheel_1.stl" scale="0.001 0.001 0.001"/>
    </geometry>
    <material name="silver"/>
  </visual>
  <collision>
    <origin xyz="-0.0 0.1 -0.05" rpy="0 0 0"/>
    <geometry>
      <mesh filename="package://diff_bot_description/meshes/right_wheel_1.stl" scale="0.001 0.001 0.001"/>
    </geometry>
  </collision>
</link>

<link name="lidar_1">
  <inertial>
    <origin xyz="-4.565484619328819e-06 0.0 0.010000000000000023" rpy="0 0 0"/>
    <mass value="0.30820940244503464"/>
    <inertia ixx="5.8e-05" iyy="5.8e-05" izz="9.6e-05" ixy="0.0" iyz="0.0" ixz="0.0"/>
  </inertial>
  <visual>
    <origin xyz="-0.065117 -0.0 -0.095" rpy="0 0 0"/>
    <geometry>
      <mesh filename="package://diff_bot_description/meshes/lidar_1.stl" scale="0.001 0.001 0.001"/>
    </geometry>
    <material name="silver"/>
  </visual>
  <collision>
    <origin xyz="-0.065117 -0.0 -0.095" rpy="0 0 0"/>
    <geometry>
      <mesh filename="package://diff_bot_description/meshes/lidar_1.stl" scale="0.001 0.001 0.001"/>
    </geometry>
  </collision>
</link>

<joint name="left_joint" type="continuous">
  <origin xyz="0.0 0.1 0.05" rpy="0 0 0"/>
  <parent link="base_link"/>
  <child link="left_wheel_1"/>
  <axis xyz="0.0 1.0 0.0"/>
</joint>

<joint name="right_joint" type="continuous">
  <origin xyz="0.0 -0.1 0.05" rpy="0 0 0"/>
  <parent link="base_link"/>
  <child link="right_wheel_1"/>
  <axis xyz="0.0 -1.0 0.0"/>
</joint>

<joint name="lidar_joint" type="continuous">
  <origin xyz="0.065117 0.0 0.095" rpy="0 0 0"/>
  <parent link="base_link"/>
  <child link="lidar_1"/>
  <axis xyz="0.0 0.0 1.0"/>
</joint>

</robot>
